<?xml version="1.0"?>

<robot xmlns:xacro="http://www.ros.org/wiki/xacro" 
	name="infantry_xacro">
  

  <link
    name="base_link">
    <inertial>
      <origin
        xyz="0.0 0 0"
        rpy="0 0 0" />
      <mass
        value="7.625" />
      <inertia
        ixx="0.10311"
        ixy="-9.0391E-05"
        ixz="0.0071078"
        iyy="0.24575"
        iyz="2.1083E-05"
        izz="0.32438" />
    </inertial>
    <visual>
      <origin
        xyz="0 0 0"
        rpy="0 0 0" />
      <geometry>
        <mesh
          filename="package://gazebo_envir/meshes/base_link.STL" />
      </geometry>
      <material
        name="">
        <color
          rgba="0 0 0 1" />
      </material>
    </visual>
    <collision>
      <origin
        xyz="0 0 0"
        rpy="0 0 0" />
      <geometry>
        <mesh
          filename="package://gazebo_envir/meshes/base_link.STL" />
      </geometry>
    </collision>
  </link>
  <link
    name="fl_wheel_Link">
    <inertial>
      <origin
        xyz="-5.232E-06 0.014616 -9.0427E-06"
        rpy="0 0 0" />
      <mass
        value="0.86078" />
      <inertia
        ixx="0.0015361"
        ixy="1.6456E-06"
        ixz="-2.0131E-06"
        iyy="0.002844"
        iyz="-9.5351E-07"
        izz="0.0015337" />
    </inertial>
    <visual>
      <origin
        xyz="0 0 0"
        rpy="0 0 0" />
      <geometry>
        <mesh
          filename="package://gazebo_envir/meshes/fl_wheel_Link.STL" />
      </geometry>
      <material
        name="">
        <color
          rgba="1 0 0 1" />
      </material>
    </visual>
    <collision>
      <origin
        xyz="0 0 0"
        rpy="0 0 0" />
      <geometry>
        <mesh
          filename="package://gazebo_envir/meshes/fl_wheel_Link.STL" />
      </geometry>
    </collision>
  </link>
  <joint
    name="base_link_to_fl_wheel_joint"
    type="continuous">
    <origin
      xyz="-0.21206 -0.2003 0.0022"
      rpy="0 0 -3.1415926" />
    <parent
      link="base_link" />
    <child
      link="fl_wheel_Link" />
    <axis
      xyz="0 1 0" />
  </joint>
  <link
    name="fr_wheel_Link">
    <inertial>
      <origin
        xyz="0.00010086 -0.014551 4.8285E-05"
        rpy="0 0 0" />
      <mass
        value="0.86078" />
      <inertia
        ixx="0.0015355"
        ixy="4.8831E-07"
        ixz="1.8067E-06"
        iyy="0.002844"
        iyz="9.4618E-08"
        izz="0.0015338" />
    </inertial>
    <visual>
      <origin
        xyz="0 0 0"
        rpy="0 0 0" />
      <geometry>
        <mesh
          filename="package://gazebo_envir/meshes/fr_wheel_Link.STL" />
      </geometry>
      <material
        name="">
        <color
          rgba="0.79216 0.81961 0.93333 1" />
      </material>
    </visual>
    <collision>
      <origin
        xyz="0 0 0"
        rpy="0 0 0" />
      <geometry>
        <mesh
          filename="package://gazebo_envir/meshes/fr_wheel_Link.STL" />
      </geometry>
    </collision>
  </link>
  <joint
    name="base_link_to_fr_wheel_joint"
    type="continuous">
    <origin
      xyz="-0.21206 0.2009 0.0022"
      rpy="0 0 -3.1415926" />
    <parent
      link="base_link" />
    <child
      link="fr_wheel_Link" />
    <axis
      xyz="0 -1 0" />
  </joint>
  <link
    name="br_wheel_Link">
    <inertial>
      <origin
        xyz="-5.2323E-06 -0.014549 -9.0423E-06"
        rpy="0 0 0" />
      <mass
        value="0.86078" />
      <inertia
        ixx="0.0015361"
        ixy="1.6481E-06"
        ixz="-2.0131E-06"
        iyy="0.002844"
        iyz="-9.4912E-07"
        izz="0.0015338" />
    </inertial>
    <visual>
      <origin
        xyz="0 0 0"
        rpy="0 0 0" />
      <geometry>
        <mesh
          filename="package://gazebo_envir/meshes/br_wheel_Link.STL" />
      </geometry>
      <material
        name="">
        <color
          rgba="0.79216 0.81961 0.93333 1" />
      </material>
    </visual>
    <collision>
      <origin
        xyz="0 0 0"
        rpy="0 0 0" />
      <geometry>
        <mesh
          filename="package://gazebo_envir/meshes/br_wheel_Link.STL" />
      </geometry>
    </collision>
  </link>
  <joint
    name="base_link_to_br_wheel_joint"
    type="continuous">
    <origin
      xyz="0.21194 0.2003 0.0022"
      rpy="0 0 3.1415926" />
    <parent
      link="base_link" />
    <child
      link="br_wheel_Link" />
    <axis
      xyz="0 1 0" />
  </joint>
  <link
    name="bl_wheel_Link">
    <inertial>
      <origin
        xyz="0.00010086 0.014592 4.8286E-05"
        rpy="0 0 0" />
      <mass
        value="0.86078" />
      <inertia
        ixx="0.0015355"
        ixy="5.3543E-07"
        ixz="1.8067E-06"
        iyy="0.002844"
        iyz="1.1717E-07"
        izz="0.0015337" />
    </inertial>
    <visual>
      <origin
        xyz="0 0 0"
        rpy="0 0 0" />
      <geometry>
        <mesh
          filename="package://gazebo_envir/meshes/bl_wheel_Link.STL" />
      </geometry>
      <material
        name="">
        <color
          rgba="0.75294 0.75294 0.75294 1" />
      </material>
    </visual>
    <collision>
      <origin
        xyz="0 0 0"
        rpy="0 0 0" />
      <geometry>
        <mesh
          filename="package://gazebo_envir/meshes/bl_wheel_Link.STL" />
      </geometry>
    </collision>
  </link>
  <joint
    name="base_link_to_bl_wheel_joint"
    type="continuous">
    <origin
      xyz="0.21194 -0.2009 0.0022"
      rpy="0 0 -3.1415926" />
    <parent
      link="base_link" />
    <child
      link="bl_wheel_Link" />
    <axis
      xyz="0 -1 0" />
  </joint>
  
  


  
  <link
    name="laser_Link">
    <inertial>
      <origin
        xyz="-0.00019454 1.2441E-18 0.027108"
        rpy="0 0 0" />
      <mass
        value="0.12185" />
      <inertia
        ixx="6.3159E-05"
        ixy="-9.0976E-22"
        ixz="-4.4573E-07"
        iyy="6.3776E-05"
        iyz="-1.8492E-21"
        izz="4.2072E-05" />
    </inertial>
    <visual>
      <origin
        xyz="0 0 0"
        rpy="0 0 0" />
      <geometry>
        <mesh
          filename="package://gazebo_envir/meshes/laser_Link.STL" />
      </geometry>
      <material
        name="">
        <color
          rgba="0.75294 0.75294 0.75294 1" />
      </material>
    </visual>
    <collision>
      <origin
        xyz="0 0 0"
        rpy="0 0 0" />
      <geometry>
        <mesh
          filename="package://gazebo_envir/meshes/laser_Link.STL" />
      </geometry>
    </collision>
  </link>
  <joint
    name="base_link_to_laser_joint"
    type="fixed">
    <origin
      xyz="0 0 0.2"
      rpy="0 0 0" />
    <parent
      link="base_link" />
    <child
      link="laser_Link" />
    <axis
      xyz="0 0 0" />
  </joint>
  
</robot>
